2024-03-02 23:01:22,759 - ERROR - Error al ejecutar la consulta SELECT: (MySQLdb.OperationalError) (1049, "Unknown database 'importaciones_olap'")
(Background on this error at: https://sqlalche.me/e/20/e3q8)
Traceback (most recent call last):
  File "D:\CURSO DE DATAPATH\BOOTCAMP\ETL con python\pythonetl\lib\site-packages\sqlalchemy\engine\base.py", line 145, in __init__
    self._dbapi_connection = engine.raw_connection()
  File "D:\CURSO DE DATAPATH\BOOTCAMP\ETL con python\pythonetl\lib\site-packages\sqlalchemy\engine\base.py", line 3282, in raw_connection
    return self.pool.connect()
  File "D:\CURSO DE DATAPATH\BOOTCAMP\ETL con python\pythonetl\lib\site-packages\sqlalchemy\pool\base.py", line 449, in connect
    return _ConnectionFairy._checkout(self)
  File "D:\CURSO DE DATAPATH\BOOTCAMP\ETL con python\pythonetl\lib\site-packages\sqlalchemy\pool\base.py", line 1263, in _checkout
    fairy = _ConnectionRecord.checkout(pool)
  File "D:\CURSO DE DATAPATH\BOOTCAMP\ETL con python\pythonetl\lib\site-packages\sqlalchemy\pool\base.py", line 712, in checkout
    rec = pool._do_get()
  File "D:\CURSO DE DATAPATH\BOOTCAMP\ETL con python\pythonetl\lib\site-packages\sqlalchemy\pool\impl.py", line 168, in _do_get
    with util.safe_reraise():
  File "D:\CURSO DE DATAPATH\BOOTCAMP\ETL con python\pythonetl\lib\site-packages\sqlalchemy\util\langhelpers.py", line 146, in __exit__
    raise exc_value.with_traceback(exc_tb)
  File "D:\CURSO DE DATAPATH\BOOTCAMP\ETL con python\pythonetl\lib\site-packages\sqlalchemy\pool\impl.py", line 166, in _do_get
    return self._create_connection()
  File "D:\CURSO DE DATAPATH\BOOTCAMP\ETL con python\pythonetl\lib\site-packages\sqlalchemy\pool\base.py", line 390, in _create_connection
    return _ConnectionRecord(self)
  File "D:\CURSO DE DATAPATH\BOOTCAMP\ETL con python\pythonetl\lib\site-packages\sqlalchemy\pool\base.py", line 674, in __init__
    self.__connect()
  File "D:\CURSO DE DATAPATH\BOOTCAMP\ETL con python\pythonetl\lib\site-packages\sqlalchemy\pool\base.py", line 900, in __connect
    with util.safe_reraise():
  File "D:\CURSO DE DATAPATH\BOOTCAMP\ETL con python\pythonetl\lib\site-packages\sqlalchemy\util\langhelpers.py", line 146, in __exit__
    raise exc_value.with_traceback(exc_tb)
  File "D:\CURSO DE DATAPATH\BOOTCAMP\ETL con python\pythonetl\lib\site-packages\sqlalchemy\pool\base.py", line 896, in __connect
    self.dbapi_connection = connection = pool._invoke_creator(self)
  File "D:\CURSO DE DATAPATH\BOOTCAMP\ETL con python\pythonetl\lib\site-packages\sqlalchemy\engine\create.py", line 643, in connect
    return dialect.connect(*cargs, **cparams)
  File "D:\CURSO DE DATAPATH\BOOTCAMP\ETL con python\pythonetl\lib\site-packages\sqlalchemy\engine\default.py", line 616, in connect
    return self.loaded_dbapi.connect(*cargs, **cparams)
  File "D:\CURSO DE DATAPATH\BOOTCAMP\ETL con python\pythonetl\lib\site-packages\MySQLdb\__init__.py", line 121, in Connect
    return Connection(*args, **kwargs)
  File "D:\CURSO DE DATAPATH\BOOTCAMP\ETL con python\pythonetl\lib\site-packages\MySQLdb\connections.py", line 195, in __init__
    super().__init__(*args, **kwargs2)
MySQLdb.OperationalError: (1049, "Unknown database 'importaciones_olap'")

The above exception was the direct cause of the following exception:

Traceback (most recent call last):
  File "d:\CURSO DE DATAPATH\BOOTCAMP\ETL con python\database\mysql_conexion_olap.py", line 170, in procesar_script_olap
    self.session.execute(text("CREATE DATABASE IF NOT EXISTS importaciones_olap"))
  File "D:\CURSO DE DATAPATH\BOOTCAMP\ETL con python\pythonetl\lib\site-packages\sqlalchemy\orm\session.py", line 2306, in execute
    return self._execute_internal(
  File "D:\CURSO DE DATAPATH\BOOTCAMP\ETL con python\pythonetl\lib\site-packages\sqlalchemy\orm\session.py", line 2181, in _execute_internal
    conn = self._connection_for_bind(bind)
  File "D:\CURSO DE DATAPATH\BOOTCAMP\ETL con python\pythonetl\lib\site-packages\sqlalchemy\orm\session.py", line 2050, in _connection_for_bind
    return trans._connection_for_bind(engine, execution_options)
  File "<string>", line 2, in _connection_for_bind
  File "D:\CURSO DE DATAPATH\BOOTCAMP\ETL con python\pythonetl\lib\site-packages\sqlalchemy\orm\state_changes.py", line 139, in _go
    ret_value = fn(self, *arg, **kw)
  File "D:\CURSO DE DATAPATH\BOOTCAMP\ETL con python\pythonetl\lib\site-packages\sqlalchemy\orm\session.py", line 1144, in _connection_for_bind
    conn = bind.connect()
  File "D:\CURSO DE DATAPATH\BOOTCAMP\ETL con python\pythonetl\lib\site-packages\sqlalchemy\engine\base.py", line 3258, in connect
    return self._connection_cls(self)
  File "D:\CURSO DE DATAPATH\BOOTCAMP\ETL con python\pythonetl\lib\site-packages\sqlalchemy\engine\base.py", line 147, in __init__
    Connection._handle_dbapi_exception_noconnection(
  File "D:\CURSO DE DATAPATH\BOOTCAMP\ETL con python\pythonetl\lib\site-packages\sqlalchemy\engine\base.py", line 2422, in _handle_dbapi_exception_noconnection
    raise sqlalchemy_exception.with_traceback(exc_info[2]) from e
  File "D:\CURSO DE DATAPATH\BOOTCAMP\ETL con python\pythonetl\lib\site-packages\sqlalchemy\engine\base.py", line 145, in __init__
    self._dbapi_connection = engine.raw_connection()
  File "D:\CURSO DE DATAPATH\BOOTCAMP\ETL con python\pythonetl\lib\site-packages\sqlalchemy\engine\base.py", line 3282, in raw_connection
    return self.pool.connect()
  File "D:\CURSO DE DATAPATH\BOOTCAMP\ETL con python\pythonetl\lib\site-packages\sqlalchemy\pool\base.py", line 449, in connect
    return _ConnectionFairy._checkout(self)
  File "D:\CURSO DE DATAPATH\BOOTCAMP\ETL con python\pythonetl\lib\site-packages\sqlalchemy\pool\base.py", line 1263, in _checkout
    fairy = _ConnectionRecord.checkout(pool)
  File "D:\CURSO DE DATAPATH\BOOTCAMP\ETL con python\pythonetl\lib\site-packages\sqlalchemy\pool\base.py", line 712, in checkout
    rec = pool._do_get()
  File "D:\CURSO DE DATAPATH\BOOTCAMP\ETL con python\pythonetl\lib\site-packages\sqlalchemy\pool\impl.py", line 168, in _do_get
    with util.safe_reraise():
  File "D:\CURSO DE DATAPATH\BOOTCAMP\ETL con python\pythonetl\lib\site-packages\sqlalchemy\util\langhelpers.py", line 146, in __exit__
    raise exc_value.with_traceback(exc_tb)
  File "D:\CURSO DE DATAPATH\BOOTCAMP\ETL con python\pythonetl\lib\site-packages\sqlalchemy\pool\impl.py", line 166, in _do_get
    return self._create_connection()
  File "D:\CURSO DE DATAPATH\BOOTCAMP\ETL con python\pythonetl\lib\site-packages\sqlalchemy\pool\base.py", line 390, in _create_connection
    return _ConnectionRecord(self)
  File "D:\CURSO DE DATAPATH\BOOTCAMP\ETL con python\pythonetl\lib\site-packages\sqlalchemy\pool\base.py", line 674, in __init__
    self.__connect()
  File "D:\CURSO DE DATAPATH\BOOTCAMP\ETL con python\pythonetl\lib\site-packages\sqlalchemy\pool\base.py", line 900, in __connect
    with util.safe_reraise():
  File "D:\CURSO DE DATAPATH\BOOTCAMP\ETL con python\pythonetl\lib\site-packages\sqlalchemy\util\langhelpers.py", line 146, in __exit__
    raise exc_value.with_traceback(exc_tb)
  File "D:\CURSO DE DATAPATH\BOOTCAMP\ETL con python\pythonetl\lib\site-packages\sqlalchemy\pool\base.py", line 896, in __connect
    self.dbapi_connection = connection = pool._invoke_creator(self)
  File "D:\CURSO DE DATAPATH\BOOTCAMP\ETL con python\pythonetl\lib\site-packages\sqlalchemy\engine\create.py", line 643, in connect
    return dialect.connect(*cargs, **cparams)
  File "D:\CURSO DE DATAPATH\BOOTCAMP\ETL con python\pythonetl\lib\site-packages\sqlalchemy\engine\default.py", line 616, in connect
    return self.loaded_dbapi.connect(*cargs, **cparams)
  File "D:\CURSO DE DATAPATH\BOOTCAMP\ETL con python\pythonetl\lib\site-packages\MySQLdb\__init__.py", line 121, in Connect
    return Connection(*args, **kwargs)
  File "D:\CURSO DE DATAPATH\BOOTCAMP\ETL con python\pythonetl\lib\site-packages\MySQLdb\connections.py", line 195, in __init__
    super().__init__(*args, **kwargs2)
sqlalchemy.exc.OperationalError: (MySQLdb.OperationalError) (1049, "Unknown database 'importaciones_olap'")
(Background on this error at: https://sqlalche.me/e/20/e3q8)
